Workbook
Name p_PassTotal: Lists!$N$4
Name p_PassExt: Lists!$N$5
Name p_SgpaDiv: Lists!$N$6
Name p_Distinction: Lists!$N$7
Name p_AttMin: Lists!$N$8
Name p_AttGood: Lists!$N$9
Name p_AttExc: Lists!$N$10
Name w_Fb: Lists!$N$11
Name w_Pass: Lists!$N$12
Name w_Res: Lists!$N$13
Name w_Exp: Lists!$N$14
Name p_ResCap: Lists!$N$15
Name p_ExpCap: Lists!$N$16
Name p_Rate1: Lists!$N$17
Name p_Rate2: Lists!$N$18
Name p_Rate3: Lists!$N$19
Name p_CoursePass: Lists!$N$20
Name fSt_B: 'Student Dashboard'!$C$5
Name cSt_B: Calc!$C$4
Name fSt_S: 'Student Dashboard'!$E$5
Name cSt_S: Calc!$C$5
Name fSt_Y: 'Student Dashboard'!$G$5
Name cSt_Y: Calc!$C$6
Name fAt_B: 'Attendance Dashboard'!$C$5
Name cAt_B: Calc!$C$7
Name fAt_S: 'Attendance Dashboard'!$E$5
Name cAt_S: Calc!$C$8
Name fAt_Y: 'Attendance Dashboard'!$G$5
Name cAt_Y: Calc!$C$9
Name fCo_B: 'Course Dashboard'!$C$5
Name cCo_B: Calc!$C$10
Name fCo_S: 'Course Dashboard'!$E$5
Name cCo_S: Calc!$C$11
Name fCo_Y: 'Course Dashboard'!$G$5
Name cCo_Y: Calc!$C$12
Name fFa_B: 'Faculty Dashboard'!$C$5
Name cFa_B: Calc!$C$13
Name fFa_Y: 'Faculty Dashboard'!$E$5
Name cFa_Y: Calc!$C$14
Name fPl_B: 'Placement Dashboard'!$C$5
Name cPl_B: Calc!$C$15
Name fPl_Y: 'Placement Dashboard'!$E$5
Name cPl_Y: Calc!$C$16
Name fOv_B: 'Overview'!$C$5
Name cOv_B: Calc!$C$17
Name fOv_Y: 'Overview'!$E$5
Name cOv_Y: Calc!$C$18

Sheet Overview
B1: Education & Student Analytics System
B2: Executive overview of all five modules | filter by Branch and Year
B3: « Overview | D3: Students | E3: Attendance | F3: Faculty | G3: Placements | I3: Courses | K3: Instructions | M3: Lists »
B5: Branch | C5: All | D5: Year | E5: All | I5: Choose 'All' to clear a filter. Branch charts compare all branches (Year filter applies). Click any button above to jump to a module.
B7: STUDENTS ASSESSED | E7: AVERAGE ATTENDANCE | I7: PLACEMENT RATE | L7: AVG FACULTY SCORE
B8: =COUNTIFS(tblStudents[Branch],cOv_B,tblStudents[Year],cOv_Y) -> 240 | E8: =IFERROR(AVERAGEIFS(tblAttendance[Attendance %],tblAttendance[Branch],cOv_B,tblAttendance[Year],cOv_Y),0) -> 0.8345168 | I8: =IFERROR(COUNTIFS(tblPlacements[Branch],cOv_B,tblPlacements[Year],cOv_Y,tblPlacements[Status],"Placed")/COUNTIFS(tblPlacements[Branch],cOv_B,tblPlacements[Year],cOv_Y),0) -> 0.76 | L8: =IFERROR(AVERAGEIFS(tblFaculty[Performance Score],tblFaculty[Department],cOv_B,tblFaculty[Year],cOv_Y),0) -> 76.45
B10: ="Pass rate: "&TEXT(IFERROR(COUNTIFS(tblStudents[Branch],cOv_B,tblStudents[Year],cOv_Y,tblStudents[Result],"Pass")/COUNTIFS(tblStudents[Branch],cOv_B,tblStudents[Year],cOv_Y),0),"0.0%") -> Pass rate: 89.2% | E10: =COUNTIFS(tblAttendance[Branch],cOv_B,tblAttendance[Year],cOv_Y,tblAttendance[Attendance %],"<"&p_AttMin)&" students below "&TEXT(p_AttMin,"0%") -> 42 students below 75% | I10: ="Average package: "&TEXT(IFERROR(AVERAGEIFS(tblPlacements[Package LPA],tblPlacements[Branch],cOv_B,tblPlacements[Year],cOv_Y,tblPlacements[Status],"Placed"),0),"0.0")&" LPA" -> Average package: 9.6 LPA | L10: ="Course pass rate: "&TEXT(IFERROR(SUMIFS(tblCourses[Passed],tblCourses[Branch],cOv_B,tblCourses[Year],cOv_Y)/SUMIFS(tblCourses[Enrolled],tblCourses[Branch],cOv_B,tblCourses[Year],cOv_Y),0),"0.0%") -> Course pass rate: 89.7%
B42: BRANCH LEADERBOARD (composite = average of pass, attendance & placement rates) | I42: MODULE SCORECARD (current filter selection)
B43: # | C43: Branch | D43: Composite | E43: Pass Rate | F43: Attendance | G43: Placement | I43: # | J43: Module | K43: Headline metric | M43: Value | N43: Open
B44: 1 | C44: =INDEX(Calc!$A$164:$A$168,MATCH(LARGE(Calc!$I$164:$I$168,$B44),Calc!$I$164:$I$168,0)) -> IT | D44: =INDEX(Calc!$H$164:$H$168,MATCH(LARGE(Calc!$I$164:$I$168,$B44),Calc!$I$164:$I$168,0)) -> 0.87804501 | E44: =INDEX(Calc!$C$164:$C$168,MATCH(LARGE(Calc!$I$164:$I$168,$B44),Calc!$I$164:$I$168,0)) -> 0.92105263 | F44: =INDEX(Calc!$D$164:$D$168,MATCH(LARGE(Calc!$I$164:$I$168,$B44),Calc!$I$164:$I$168,0)) -> 0.84211465 | G44: =INDEX(Calc!$E$164:$E$168,MATCH(LARGE(Calc!$I$164:$I$168,$B44),Calc!$I$164:$I$168,0)) -> 0.87096774 | I44: 1 | J44: Student Performance | K44: Pass rate | M44: =IFERROR(COUNTIFS(tblStudents[Branch],cOv_B,tblStudents[Year],cOv_Y,tblStudents[Result],"Pass")/COUNTIFS(tblStudents[Branch],cOv_B,tblStudents[Year],cOv_Y),0) -> 0.89166667 | N44: Open »
B45: 2 | C45: =INDEX(Calc!$A$164:$A$168,MATCH(LARGE(Calc!$I$164:$I$168,$B45),Calc!$I$164:$I$168,0)) -> CSE | D45: =INDEX(Calc!$H$164:$H$168,MATCH(LARGE(Calc!$I$164:$I$168,$B45),Calc!$I$164:$I$168,0)) -> 0.86225022 | E45: =INDEX(Calc!$C$164:$C$168,MATCH(LARGE(Calc!$I$164:$I$168,$B45),Calc!$I$164:$I$168,0)) -> 0.90322581 | F45: =INDEX(Calc!$D$164:$D$168,MATCH(LARGE(Calc!$I$164:$I$168,$B45),Calc!$I$164:$I$168,0)) -> 0.85425657 | G45: =INDEX(Calc!$E$164:$E$168,MATCH(LARGE(Calc!$I$164:$I$168,$B45),Calc!$I$164:$I$168,0)) -> 0.82926829 | I45: 2 | J45: Attendance | K45: Average attendance | M45: =IFERROR(AVERAGEIFS(tblAttendance[Attendance %],tblAttendance[Branch],cOv_B,tblAttendance[Year],cOv_Y),0) -> 0.8345168 | N45: Open »
B46: 3 | C46: =INDEX(Calc!$A$164:$A$168,MATCH(LARGE(Calc!$I$164:$I$168,$B46),Calc!$I$164:$I$168,0)) -> ECE | D46: =INDEX(Calc!$H$164:$H$168,MATCH(LARGE(Calc!$I$164:$I$168,$B46),Calc!$I$164:$I$168,0)) -> 0.82825864 | E46: =INDEX(Calc!$C$164:$C$168,MATCH(LARGE(Calc!$I$164:$I$168,$B46),Calc!$I$164:$I$168,0)) -> 0.90740741 | F46: =INDEX(Calc!$D$164:$D$168,MATCH(LARGE(Calc!$I$164:$I$168,$B46),Calc!$I$164:$I$168,0)) -> 0.84052639 | G46: =INDEX(Calc!$E$164:$E$168,MATCH(LARGE(Calc!$I$164:$I$168,$B46),Calc!$I$164:$I$168,0)) -> 0.73684211 | I46: 3 | J46: Faculty Performance | K46: Avg performance score | M46: =IFERROR(AVERAGEIFS(tblFaculty[Performance Score],tblFaculty[Department],cOv_B,tblFaculty[Year],cOv_Y),0) -> 76.45 | N46: Open »
B47: 4 | C47: =INDEX(Calc!$A$164:$A$168,MATCH(LARGE(Calc!$I$164:$I$168,$B47),Calc!$I$164:$I$168,0)) -> CE | D47: =INDEX(Calc!$H$164:$H$168,MATCH(LARGE(Calc!$I$164:$I$168,$B47),Calc!$I$164:$I$168,0)) -> 0.76773135 | E47: =INDEX(Calc!$C$164:$C$168,MATCH(LARGE(Calc!$I$164:$I$168,$B47),Calc!$I$164:$I$168,0)) -> 0.91891892 | F47: =INDEX(Calc!$D$164:$D$168,MATCH(LARGE(Calc!$I$164:$I$168,$B47),Calc!$I$164:$I$168,0)) -> 0.82871959 | G47: =INDEX(Calc!$E$164:$E$168,MATCH(LARGE(Calc!$I$164:$I$168,$B47),Calc!$I$164:$I$168,0)) -> 0.55555556 | I47: 4 | J47: Placement | K47: Placement rate | M47: =IFERROR(COUNTIFS(tblPlacements[Branch],cOv_B,tblPlacements[Year],cOv_Y,tblPlacements[Status],"Placed")/COUNTIFS(tblPlacements[Branch],cOv_B,tblPlacements[Year],cOv_Y),0) -> 0.76 | N47: Open »
B48: 5 | C48: =INDEX(Calc!$A$164:$A$168,MATCH(LARGE(Calc!$I$164:$I$168,$B48),Calc!$I$164:$I$168,0)) -> ME | D48: =INDEX(Calc!$H$164:$H$168,MATCH(LARGE(Calc!$I$164:$I$168,$B48),Calc!$I$164:$I$168,0)) -> 0.76651572 | E48: =INDEX(Calc!$C$164:$C$168,MATCH(LARGE(Calc!$I$164:$I$168,$B48),Calc!$I$164:$I$168,0)) -> 0.81632653 | F48: =INDEX(Calc!$D$164:$D$168,MATCH(LARGE(Calc!$I$164:$I$168,$B48),Calc!$I$164:$I$168,0)) -> 0.80140243 | G48: =INDEX(Calc!$E$164:$E$168,MATCH(LARGE(Calc!$I$164:$I$168,$B48),Calc!$I$164:$I$168,0)) -> 0.68181818 | I48: 5 | J48: Course Analytics | K48: Overall pass rate | M48: =IFERROR(SUMIFS(tblCourses[Passed],tblCourses[Branch],cOv_B,tblCourses[Year],cOv_Y)/SUMIFS(tblCourses[Enrolled],tblCourses[Branch],cOv_B,tblCourses[Year],cOv_Y),0) -> 0.89681979 | N48: Open »
B50: All figures are live formulas over the Excel Tables (tblStudents, tblAttendance, tblFaculty, tblPlacements, tblCourses). Replace the sample data and everything updates. See the Instructions sheet.

Sheet Student Dashboard
B1: Student Performance Analytics
B2: Results, grades and SGPA across branches and semesters | source: tblStudents
B3: « Overview | D3: Students | E3: Attendance | F3: Faculty | G3: Placements | I3: Courses | K3: Instructions | M3: Data »
B5: Branch | C5: All | D5: Semester | E5: All | F5: Year | G5: All | I5: Choose 'All' to clear a filter. Everything on this page recalculates instantly. Branch-comparison charts ignore the Branch filter.
B7: STUDENTS ASSESSED | E7: PASS PERCENTAGE | I7: AVERAGE SGPA (PASSED) | L7: DISTINCTION RATE
B8: =COUNTIFS(tblStudents[Branch],cSt_B,tblStudents[Semester],cSt_S,tblStudents[Year],cSt_Y) -> 240 | E8: =IFERROR(COUNTIFS(tblStudents[Branch],cSt_B,tblStudents[Semester],cSt_S,tblStudents[Year],cSt_Y,tblStudents[Result],"Pass")/COUNTIFS(tblStudents[Branch],cSt_B,tblStudents[Semester],cSt_S,tblStudents[Year],cSt_Y),0) -> 0.89166667 | I8: =IFERROR(AVERAGEIFS(tblStudents[SGPA],tblStudents[Branch],cSt_B,tblStudents[Semester],cSt_S,tblStudents[Year],cSt_Y,tblStudents[Result],"Pass"),0) -> 7.3518692 | L8: =IFERROR(COUNTIFS(tblStudents[Branch],cSt_B,tblStudents[Semester],cSt_S,tblStudents[Year],cSt_Y,tblStudents[SGPA],">="&p_Distinction)/COUNTIFS(tblStudents[Branch],cSt_B,tblStudents[Semester],cSt_S,tblStudents[Year],cSt_Y),0) -> 0.275
B10: ="Records in current selection" -> Records in current selection | E10: ="Failed: "&(COUNTIFS(tblStudents[Branch],cSt_B,tblStudents[Semester],cSt_S,tblStudents[Year],cSt_Y)-COUNTIFS(tblStudents[Branch],cSt_B,tblStudents[Semester],cSt_S,tblStudents[Year],cSt_Y,tblStudents[Result],"Pass"))&" students" -> Failed: 26 students | I10: ="Avg total marks: "&TEXT(IFERROR(AVERAGEIFS(tblStudents[Total Marks],tblStudents[Branch],cSt_B,tblStudents[Semester],cSt_S,tblStudents[Year],cSt_Y),0),"0.0")&" / 100" -> Avg total marks: 67.0 / 100 | L10: ="SGPA of "&TEXT(p_Distinction,"0.0")&" or above" -> SGPA of 8.0 or above
B42: ▲ TOP 10 STUDENTS - TOTAL MARKS | I42: ▼ BOTTOM 10 STUDENTS - TOTAL MARKS
B43: # | C43: Student | D43: Branch | E43: Sem | F43: Total | G43: SGPA | I43: # | J43: Student | K43: Branch | L43: Sem | M43: Total | N43: SGPA
B44: 1 | C44: =IFERROR(INDEX(tblStudents[Student Name],MATCH(LARGE(tblStudents[Rank Key],$B44),tblStudents[Rank Key],0)),"-") -> Deepak Siddiqui | D44: =IFERROR(INDEX(tblStudents[Branch],MATCH(LARGE(tblStudents[Rank Key],$B44),tblStudents[Rank Key],0)),"-") -> CE | E44: =IFERROR(INDEX(tblStudents[Semester],MATCH(LARGE(tblStudents[Rank Key],$B44),tblStudents[Rank Key],0)),"-") -> 3 | F44: =IFERROR(INDEX(tblStudents[Total Marks],MATCH(LARGE(tblStudents[Rank Key],$B44),tblStudents[Rank Key],0)),"-") -> 96 | G44: =IFERROR(INDEX(tblStudents[SGPA],MATCH(LARGE(tblStudents[Rank Key],$B44),tblStudents[Rank Key],0)),"-") -> 10 | I44: 1 | J44: =IFERROR(INDEX(tblStudents[Student Name],MATCH(SMALL(tblStudents[Rank Key],$I44),tblStudents[Rank Key],0)),"-") -> Ayush Shah | K44: =IFERROR(INDEX(tblStudents[Branch],MATCH(SMALL(tblStudents[Rank Key],$I44),tblStudents[Rank Key],0)),"-") -> IT | L44: =IFERROR(INDEX(tblStudents[Semester],MATCH(SMALL(tblStudents[Rank Key],$I44),tblStudents[Rank Key],0)),"-") -> 1 | M44: =IFERROR(INDEX(tblStudents[Total Marks],MATCH(SMALL(tblStudents[Rank Key],$I44),tblStudents[Rank Key],0)),"-") -> 34 | N44: =IFERROR(INDEX(tblStudents[SGPA],MATCH(SMALL(tblStudents[Rank Key],$I44),tblStudents[Rank Key],0)),"-") -> 0
B45: 2 | C45: =IFERROR(INDEX(tblStudents[Student Name],MATCH(LARGE(tblStudents[Rank Key],$B45),tblStudents[Rank Key],0)),"-") -> Gaurav Srivastava | D45: =IFERROR(INDEX(tblStudents[Branch],MATCH(LARGE(tblStudents[Rank Key],$B45),tblStudents[Rank Key],0)),"-") -> ECE | E45: =IFERROR(INDEX(tblStudents[Semester],MATCH(LARGE(tblStudents[Rank Key],$B45),tblStudents[Rank Key],0)),"-") -> 1 | F45: =IFERROR(INDEX(tblStudents[Total Marks],MATCH(LARGE(tblStudents[Rank Key],$B45),tblStudents[Rank Key],0)),"-") -> 96 | G45: =IFERROR(INDEX(tblStudents[SGPA],MATCH(LARGE(tblStudents[Rank Key],$B45),tblStudents[Rank Key],0)),"-") -> 10 | I45: 2 | J45: =IFERROR(INDEX(tblStudents[Student Name],MATCH(SMALL(tblStudents[Rank Key],$I45),tblStudents[Rank Key],0)),"-") -> Amit Malik | K45: =IFERROR(INDEX(tblStudents[Branch],MATCH(SMALL(tblStudents[Rank Key],$I45),tblStudents[Rank Key],0)),"-") -> IT | L45: =IFERROR(INDEX(tblStudents[Semester],MATCH(SMALL(tblStudents[Rank Key],$I45),tblStudents[Rank Key],0)),"-") -> 4 | M45: =IFERROR(INDEX(tblStudents[Total Marks],MATCH(SMALL(tblStudents[Rank Key],$I45),tblStudents[Rank Key],0)),"-") -> 36 | N45: =IFERROR(INDEX(tblStudents[SGPA],MATCH(SMALL(tblStudents[Rank Key],$I45),tblStudents[Rank Key],0)),"-") -> 0
B46: 3 | C46: =IFERROR(INDEX(tblStudents[Student Name],MATCH(LARGE(tblStudents[Rank Key],$B46),tblStudents[Rank Key],0)),"-") -> Ankit Kapoor | D46: =IFERROR(INDEX(tblStudents[Branch],MATCH(LARGE(tblStudents[Rank Key],$B46),tblStudents[Rank Key],0)),"-") -> CSE | E46: =IFERROR(INDEX(tblStudents[Semester],MATCH(LARGE(tblStudents[Rank Key],$B46),tblStudents[Rank Key],0)),"-") -> 5 | F46: =IFERROR(INDEX(tblStudents[Total Marks],MATCH(LARGE(tblStudents[Rank Key],$B46),tblStudents[Rank Key],0)),"-") -> 96 | G46: =IFERROR(INDEX(tblStudents[SGPA],MATCH(LARGE(tblStudents[Rank Key],$B46),tblStudents[Rank Key],0)),"-") -> 10 | I46: 3 | J46: =IFERROR(INDEX(tblStudents[Student Name],MATCH(SMALL(tblStudents[Rank Key],$I46),tblStudents[Rank Key],0)),"-") -> Diya Rawat | K46: =IFERROR(INDEX(tblStudents[Branch],MATCH(SMALL(tblStudents[Rank Key],$I46),tblStudents[Rank Key],0)),"-") -> ME | L46: =IFERROR(INDEX(tblStudents[Semester],MATCH(SMALL(tblStudents[Rank Key],$I46),tblStudents[Rank Key],0)),"-") -> 3 | M46: =IFERROR(INDEX(tblStudents[Total Marks],MATCH(SMALL(tblStudents[Rank Key],$I46),tblStudents[Rank Key],0)),"-") -> 38 | N46: =IFERROR(INDEX(tblStudents[SGPA],MATCH(SMALL(tblStudents[Rank Key],$I46),tblStudents[Rank Key],0)),"-") -> 0
B47: 4 | C47: =IFERROR(INDEX(tblStudents[Student Name],MATCH(LARGE(tblStudents[Rank Key],$B47),tblStudents[Rank Key],0)),"-") -> Rahul Kumar | D47: =IFERROR(INDEX(tblStudents[Branch],MATCH(LARGE(tblStudents[Rank Key],$B47),tblStudents[Rank Key],0)),"-") -> IT | E47: =IFERROR(INDEX(tblStudents[Semester],MATCH(LARGE(tblStudents[Rank Key],$B47),tblStudents[Rank Key],0)),"-") -> 7 | F47: =IFERROR(INDEX(tblStudents[Total Marks],MATCH(LARGE(tblStudents[Rank Key],$B47),tblStudents[Rank Key],0)),"-") -> 95 | G47: =IFERROR(INDEX(tblStudents[SGPA],MATCH(LARGE(tblStudents[Rank Key],$B47),tblStudents[Rank Key],0)),"-") -> 10 | I47: 4 | J47: =IFERROR(INDEX(tblStudents[Student Name],MATCH(SMALL(tblStudents[Rank Key],$I47),tblStudents[Rank Key],0)),"-") -> Devansh Singh | K47: =IFERROR(INDEX(tblStudents[Branch],MATCH(SMALL(tblStudents[Rank Key],$I47),tblStudents[Rank Key],0)),"-") -> ME | L47: =IFERROR(INDEX(tblStudents[Semester],MATCH(SMALL(tblStudents[Rank Key],$I47),tblStudents[Rank Key],0)),"-") -> 4 | M47: =IFERROR(INDEX(tblStudents[Total Marks],MATCH(SMALL(tblStudents[Rank Key],$I47),tblStudents[Rank Key],0)),"-") -> 38 | N47: =IFERROR(INDEX(tblStudents[SGPA],MATCH(SMALL(tblStudents[Rank Key],$I47),tblStudents[Rank Key],0)),"-") -> 0
B48: 5 | C48: =IFERROR(INDEX(tblStudents[Student Name],MATCH(LARGE(tblStudents[Rank Key],$B48),tblStudents[Rank Key],0)),"-") -> Aarushi Iyer | D48: =IFERROR(INDEX(tblStudents[Branch],MATCH(LARGE(tblStudents[Rank Key],$B48),tblStudents[Rank Key],0)),"-") -> ECE | E48: =IFERROR(INDEX(tblStudents[Semester],MATCH(LARGE(tblStudents[Rank Key],$B48),tblStudents[Rank Key],0)),"-") -> 3 | F48: =IFERROR(INDEX(tblStudents[Total Marks],MATCH(LARGE(tblStudents[Rank Key],$B48),tblStudents[Rank Key],0)),"-") -> 94 | G48: =IFERROR(INDEX(tblStudents[SGPA],MATCH(LARGE(tblStudents[Rank Key],$B48),tblStudents[Rank Key],0)),"-") -> 9.89 | I48: 5 | J48: =IFERROR(INDEX(tblStudents[Student Name],MATCH(SMALL(tblStudents[Rank Key],$I48),tblStudents[Rank Key],0)),"-") -> Tanvi Rastogi | K48: =IFERROR(INDEX(tblStudents[Branch],MATCH(SMALL(tblStudents[Rank Key],$I48),tblStudents[Rank Key],0)),"-") -> CE | L48: =IFERROR(INDEX(tblStudents[Semester],MATCH(SMALL(tblStudents[Rank Key],$I48),tblStudents[Rank Key],0)),"-") -> 7 | M48: =IFERROR(INDEX(tblStudents[Total Marks],MATCH(SMALL(tblStudents[Rank Key],$I48),tblStudents[Rank Key],0)),"-") -> 38 | N48: =IFERROR(INDEX(tblStudents[SGPA],MATCH(SMALL(tblStudents[Rank Key],$I48),tblStudents[Rank Key],0)),"-") -> 0
B49: 6 | C49: =IFERROR(INDEX(tblStudents[Student Name],MATCH(LARGE(tblStudents[Rank Key],$B49),tblStudents[Rank Key],0)),"-") -> Sneha Bansal | D49: =IFERROR(INDEX(tblStudents[Branch],MATCH(LARGE(tblStudents[Rank Key],$B49),tblStudents[Rank Key],0)),"-") -> CE | E49: =IFERROR(INDEX(tblStudents[Semester],MATCH(LARGE(tblStudents[Rank Key],$B49),tblStudents[Rank Key],0)),"-") -> 4 | F49: =IFERROR(INDEX(tblStudents[Total Marks],MATCH(LARGE(tblStudents[Rank Key],$B49),tblStudents[Rank Key],0)),"-") -> 94 | G49: =IFERROR(INDEX(tblStudents[SGPA],MATCH(LARGE(tblStudents[Rank Key],$B49),tblStudents[Rank Key],0)),"-") -> 9.89 | I49: 6 | J49: =IFERROR(INDEX(tblStudents[Student Name],MATCH(SMALL(tblStudents[Rank Key],$I49),tblStudents[Rank Key],0)),"-") -> Rohan Siddiqui | K49: =IFERROR(INDEX(tblStudents[Branch],MATCH(SMALL(tblStudents[Rank Key],$I49),tblStudents[Rank Key],0)),"-") -> ME | L49: =IFERROR(INDEX(tblStudents[Semester],MATCH(SMALL(tblStudents[Rank Key],$I49),tblStudents[Rank Key],0)),"-") -> 1 | M49: =IFERROR(INDEX(tblStudents[Total Marks],MATCH(SMALL(tblStudents[Rank Key],$I49),tblStudents[Rank Key],0)),"-") -> 38 | N49: =IFERROR(INDEX(tblStudents[SGPA],MATCH(SMALL(tblStudents[Rank Key],$I49),tblStudents[Rank Key],0)),"-") -> 0
B50: 7 | C50: =IFERROR(INDEX(tblStudents[Student Name],MATCH(LARGE(tblStudents[Rank Key],$B50),tblStudents[Rank Key],0)),"-") -> Rahul Verma | D50: =IFERROR(INDEX(tblStudents[Branch],MATCH(LARGE(tblStudents[Rank Key],$B50),tblStudents[Rank Key],0)),"-") -> ECE | E50: =IFERROR(INDEX(tblStudents[Semester],MATCH(LARGE(tblStudents[Rank Key],$B50),tblStudents[Rank Key],0)),"-") -> 7 | F50: =IFERROR(INDEX(tblStudents[Total Marks],MATCH(LARGE(tblStudents[Rank Key],$B50),tblStudents[Rank Key],0)),"-") -> 94 | G50: =IFERROR(INDEX(tblStudents[SGPA],MATCH(LARGE(tblStudents[Rank Key],$B50),tblStudents[Rank Key],0)),"-") -> 9.89 | I50: 7 | J50: =IFERROR(INDEX(tblStudents[Student Name],MATCH(SMALL(tblStudents[Rank Key],$I50),tblStudents[Rank Key],0)),"-") -> Kartik Singh | K50: =IFERROR(INDEX(tblStudents[Branch],MATCH(SMALL(tblStudents[Rank Key],$I50),tblStudents[Rank Key],0)),"-") -> CE | L50: =IFERROR(INDEX(tblStudents[Semester],MATCH(SMALL(tblStudents[Rank Key],$I50),tblStudents[Rank Key],0)),"-") -> 6 | M50: =IFERROR(INDEX(tblStudents[Total Marks],MATCH(SMALL(tblStudents[Rank Key],$I50),tblStudents[Rank Key],0)),"-") -> 39 | N50: =IFERROR(INDEX(tblStudents[SGPA],MATCH(SMALL(tblStudents[Rank Key],$I50),tblStudents[Rank Key],0)),"-") -> 0
B51: 8 | C51: =IFERROR(INDEX(tblStudents[Student Name],MATCH(LARGE(tblStudents[Rank Key],$B51),tblStudents[Rank Key],0)),"-") -> Garima Kumar | D51: =IFERROR(INDEX(tblStudents[Branch],MATCH(LARGE(tblStudents[Rank Key],$B51),tblStudents[Rank Key],0)),"-") -> IT | E51: =IFERROR(INDEX(tblStudents[Semester],MATCH(LARGE(tblStudents[Rank Key],$B51),tblStudents[Rank Key],0)),"-") -> 1 | F51: =IFERROR(INDEX(tblStudents[Total Marks],MATCH(LARGE(tblStudents[Rank Key],$B51),tblStudents[Rank Key],0)),"-") -> 93 | G51: =IFERROR(INDEX(tblStudents[SGPA],MATCH(LARGE(tblStudents[Rank Key],$B51),tblStudents[Rank Key],0)),"-") -> 9.79 | I51: 8 | J51: =IFERROR(INDEX(tblStudents[Student Name],MATCH(SMALL(tblStudents[Rank Key],$I51),tblStudents[Rank Key],0)),"-") -> Vaishnavi Ansari | K51: =IFERROR(INDEX(tblStudents[Branch],MATCH(SMALL(tblStudents[Rank Key],$I51),tblStudents[Rank Key],0)),"-") -> IT | L51: =IFERROR(INDEX(tblStudents[Semester],MATCH(SMALL(tblStudents[Rank Key],$I51),tblStudents[Rank Key],0)),"-") -> 6 | M51: =IFERROR(INDEX(tblStudents[Total Marks],MATCH(SMALL(tblStudents[Rank Key],$I51),tblStudents[Rank Key],0)),"-") -> 40 | N51: =IFERROR(INDEX(tblStudents[SGPA],MATCH(SMALL(tblStudents[Rank Key],$I51),tblStudents[Rank Key],0)),"-") -> 0
B52: 9 | C52: =IFERROR(INDEX(tblStudents[Student Name],MATCH(LARGE(tblStudents[Rank Key],$B52),tblStudents[Rank Key],0)),"-") -> Rajat Gupta | D52: =IFERROR(INDEX(tblStudents[Branch],MATCH(LARGE(tblStudents[Rank Key],$B52),tblStudents[Rank Key],0)),"-") -> CE | E52: =IFERROR(INDEX(tblStudents[Semester],MATCH(LARGE(tblStudents[Rank Key],$B52),tblStudents[Rank Key],0)),"-") -> 5 | F52: =IFERROR(INDEX(tblStudents[Total Marks],MATCH(LARGE(tblStudents[Rank Key],$B52),tblStudents[Rank Key],0)),"-") -> 93 | G52: =IFERROR(INDEX(tblStudents[SGPA],MATCH(LARGE(tblStudents[Rank Key],$B52),tblStudents[Rank Key],0)),"-") -> 9.79 | I52: 9 | J52: =IFERROR(INDEX(tblStudents[Student Name],MATCH(SMALL(tblStudents[Rank Key],$I52),tblStudents[Rank Key],0)),"-") -> Saurabh Dubey | K52: =IFERROR(INDEX(tblStudents[Branch],MATCH(SMALL(tblStudents[Rank Key],$I52),tblStudents[Rank Key],0)),"-") -> ME | L52: =IFERROR(INDEX(tblStudents[Semester],MATCH(SMALL(tblStudents[Rank Key],$I52),tblStudents[Rank Key],0)),"-") -> 2 | M52: =IFERROR(INDEX(tblStudents[Total Marks],MATCH(SMALL(tblStudents[Rank Key],$I52),tblStudents[Rank Key],0)),"-") -> 41 | N52: =IFERROR(INDEX(tblStudents[SGPA],MATCH(SMALL(tblStudents[Rank Key],$I52),tblStudents[Rank Key],0)),"-") -> 0
B53: 10 | C53: =IFERROR(INDEX(tblStudents[Student Name],MATCH(LARGE(tblStudents[Rank Key],$B53),tblStudents[Rank Key],0)),"-") -> Kartik Rastogi | D53: =IFERROR(INDEX(tblStudents[Branch],MATCH(LARGE(tblStudents[Rank Key],$B53),tblStudents[Rank Key],0)),"-") -> CSE | E53: =IFERROR(INDEX(tblStudents[Semester],MATCH(LARGE(tblStudents[Rank Key],$B53),tblStudents[Rank Key],0)),"-") -> 1 | F53: =IFERROR(INDEX(tblStudents[Total Marks],MATCH(LARGE(tblStudents[Rank Key],$B53),tblStudents[Rank Key],0)),"-") -> 92 | G53: =IFERROR(INDEX(tblStudents[SGPA],MATCH(LARGE(tblStudents[Rank Key],$B53),tblStudents[Rank Key],0)),"-") -> 9.68 | I53: 10 | J53: =IFERROR(INDEX(tblStudents[Student Name],MATCH(SMALL(tblStudents[Rank Key],$I53),tblStudents[Rank Key],0)),"-") -> Karan Iyer | K53: =IFERROR(INDEX(tblStudents[Branch],MATCH(SMALL(tblStudents[Rank Key],$I53),tblStudents[Rank Key],0)),"-") -> ECE | L53: =IFERROR(INDEX(tblStudents[Semester],MATCH(SMALL(tblStudents[Rank Key],$I53),tblStudents[Rank Key],0)),"-") -> 6 | M53: =IFERROR(INDEX(tblStudents[Total Marks],MATCH(SMALL(tblStudents[Rank Key],$I53),tblStudents[Rank Key],0)),"-") -> 41 | N53: =IFERROR(INDEX(tblStudents[SGPA],MATCH(SMALL(tblStudents[Rank Key],$I53),tblStudents[Rank Key],0)),"-") -> 0
B55: Pass = total ≥ 40 and external ≥ 24 (see Lists). SGPA = total marks ÷ 9.5, capped at 10 (passed students). Ranks respect the active filters.

Sheet Attendance Dashboard
B1: Attendance Analytics
B2: Attendance rates, eligibility shortages and links to marks | source: tblAttendance
B3: « Overview | D3: Students | E3: Attendance | F3: Faculty | G3: Placements | I3: Courses | K3: Instructions | M3: Data »
B5: Branch | C5: All | D5: Semester | E5: All | F5: Year | G5: All | I5: Choose 'All' to clear a filter. Red = below the minimum attendance threshold (75% by default, editable on Lists).
B7: STUDENTS TRACKED | E7: AVERAGE ATTENDANCE | I7: BELOW 75% (SHORTAGE) | L7: EXCELLENT (90%+)
B8: =COUNTIFS(tblAttendance[Branch],cAt_B,tblAttendance[Semester],cAt_S,tblAttendance[Year],cAt_Y) -> 240 | E8: =IFERROR(AVERAGEIFS(tblAttendance[Attendance %],tblAttendance[Branch],cAt_B,tblAttendance[Semester],cAt_S,tblAttendance[Year],cAt_Y),0) -> 0.8345168 | I8: =COUNTIFS(tblAttendance[Branch],cAt_B,tblAttendance[Semester],cAt_S,tblAttendance[Year],cAt_Y,tblAttendance[Attendance %],"<"&p_AttMin) -> 42 | L8: =COUNTIFS(tblAttendance[Branch],cAt_B,tblAttendance[Semester],cAt_S,tblAttendance[Year],cAt_Y,tblAttendance[Attendance %],">="&p_AttExc) -> 64
B10: ="Records in current selection" -> Records in current selection | E10: ="Minimum required: "&TEXT(p_AttMin,"0%") -> Minimum required: 75% | I10: =TEXT(IFERROR(COUNTIFS(tblAttendance[Branch],cAt_B,tblAttendance[Semester],cAt_S,tblAttendance[Year],cAt_Y,tblAttendance[Attendance %],"<"&p_AttMin)/COUNTIFS(tblAttendance[Branch],cAt_B,tblAttendance[Semester],cAt_S,tblAttendance[Year],cAt_Y),0),"0.0%")&" of students at risk" -> 17.5% of students at risk | L10: =TEXT(IFERROR(COUNTIFS(tblAttendance[Branch],cAt_B,tblAttendance[Semester],cAt_S,tblAttendance[Year],cAt_Y,tblAttendance[Attendance %],">="&p_AttExc)/COUNTIFS(tblAttendance[Branch],cAt_B,tblAttendance[Semester],cAt_S,tblAttendance[Year],cAt_Y),0),"0.0%")&" of students" -> 26.7% of students
B42: ▲ TOP 10 - HIGHEST ATTENDANCE | I42: ▼ BOTTOM 10 - LOWEST ATTENDANCE (AT RISK)
B43: # | C43: Student | D43: Branch | E43: Sem | F43: Attend. | G43: Status | I43: # | J43: Student | K43: Branch | L43: Sem | M43: Attend. | N43: Status
B44: 1 | C44: =IFERROR(INDEX(tblAttendance[Student Name],MATCH(LARGE(tblAttendance[Rank Key],$B44),tblAttendance[Rank Key],0)),"-") -> Parth Chauhan | D44: =IFERROR(INDEX(tblAttendance[Branch],MATCH(LARGE(tblAttendance[Rank Key],$B44),tblAttendance[Rank Key],0)),"-") -> CSE | E44: =IFERROR(INDEX(tblAttendance[Semester],MATCH(LARGE(tblAttendance[Rank Key],$B44),tblAttendance[Rank Key],0)),"-") -> 3 | F44: =IFERROR(INDEX(tblAttendance[Attendance %],MATCH(LARGE(tblAttendance[Rank Key],$B44),tblAttendance[Rank Key],0)),"-") -> 0.98947368 | G44: =IFERROR(INDEX(tblAttendance[Status],MATCH(LARGE(tblAttendance[Rank Key],$B44),tblAttendance[Rank Key],0)),"-") -> Excellent | I44: 1 | J44: =IFERROR(INDEX(tblAttendance[Student Name],MATCH(SMALL(tblAttendance[Rank Key],$I44),tblAttendance[Rank Key],0)),"-") -> Devansh Singh | K44: =IFERROR(INDEX(tblAttendance[Branch],MATCH(SMALL(tblAttendance[Rank Key],$I44),tblAttendance[Rank Key],0)),"-") -> ME | L44: =IFERROR(INDEX(tblAttendance[Semester],MATCH(SMALL(tblAttendance[Rank Key],$I44),tblAttendance[Rank Key],0)),"-") -> 4 | M44: =IFERROR(INDEX(tblAttendance[Attendance %],MATCH(SMALL(tblAttendance[Rank Key],$I44),tblAttendance[Rank Key],0)),"-") -> 0.60818713 | N44: =IFERROR(INDEX(tblAttendance[Status],MATCH(SMALL(tblAttendance[Rank Key],$I44),tblAttendance[Rank Key],0)),"-") -> Shortage
B45: 2 | C45: =IFERROR(INDEX(tblAttendance[Student Name],MATCH(LARGE(tblAttendance[Rank Key],$B45),tblAttendance[Rank Key],0)),"-") -> Jhanvi Kumar | D45: =IFERROR(INDEX(tblAttendance[Branch],MATCH(LARGE(tblAttendance[Rank Key],$B45),tblAttendance[Rank Key],0)),"-") -> ECE | E45: =IFERROR(INDEX(tblAttendance[Semester],MATCH(LARGE(tblAttendance[Rank Key],$B45),tblAttendance[Rank Key],0)),"-") -> 8 | F45: =IFERROR(INDEX(tblAttendance[Attendance %],MATCH(LARGE(tblAttendance[Rank Key],$B45),tblAttendance[Rank Key],0)),"-") -> 0.98941799 | G45: =IFERROR(INDEX(tblAttendance[Status],MATCH(LARGE(tblAttendance[Rank Key],$B45),tblAttendance[Rank Key],0)),"-") -> Excellent | I45: 2 | J45: =IFERROR(INDEX(tblAttendance[Student Name],MATCH(SMALL(tblAttendance[Rank Key],$I45),tblAttendance[Rank Key],0)),"-") -> Mohit Srivastava | K45: =IFERROR(INDEX(tblAttendance[Branch],MATCH(SMALL(tblAttendance[Rank Key],$I45),tblAttendance[Rank Key],0)),"-") -> CSE | L45: =IFERROR(INDEX(tblAttendance[Semester],MATCH(SMALL(tblAttendance[Rank Key],$I45),tblAttendance[Rank Key],0)),"-") -> 8 | M45: =IFERROR(INDEX(tblAttendance[Attendance %],MATCH(SMALL(tblAttendance[Rank Key],$I45),tblAttendance[Rank Key],0)),"-") -> 0.61490683 | N45: =IFERROR(INDEX(tblAttendance[Status],MATCH(SMALL(tblAttendance[Rank Key],$I45),tblAttendance[Rank Key],0)),"-") -> Shortage
B46: 3 | C46: =IFERROR(INDEX(tblAttendance[Student Name],MATCH(LARGE(tblAttendance[Rank Key],$B46),tblAttendance[Rank Key],0)),"-") -> Pallavi Srivastava | D46: =IFERROR(INDEX(tblAttendance[Branch],MATCH(LARGE(tblAttendance[Rank Key],$B46),tblAttendance[Rank Key],0)),"-") -> ECE | E46: =IFERROR(INDEX(tblAttendance[Semester],MATCH(LARGE(tblAttendance[Rank Key],$B46),tblAttendance[Rank Key],0)),"-") -> 6 | F46: =IFERROR(INDEX(tblAttendance[Attendance %],MATCH(LARGE(tblAttendance[Rank Key],$B46),tblAttendance[Rank Key],0)),"-") -> 0.98895028 | G46: =IFERROR(INDEX(tblAttendance[Status],MATCH(LARGE(tblAttendance[Rank Key],$B46),tblAttendance[Rank Key],0)),"-") -> Excellent | I46: 3 | J46: =IFERROR(INDEX(tblAttendance[Student Name],MATCH(SMALL(tblAttendance[Rank Key],$I46),tblAttendance[Rank Key],0)),"-") -> Kartik Singh | K46: =IFERROR(INDEX(tblAttendance[Branch],MATCH(SMALL(tblAttendance[Rank Key],$I46),tblAttendance[Rank Key],0)),"-") -> CE | L46: =IFERROR(INDEX(tblAttendance[Semester],MATCH(SMALL(tblAttendance[Rank Key],$I46),tblAttendance[Rank Key],0)),"-") -> 6 | M46: =IFERROR(INDEX(tblAttendance[Attendance %],MATCH(SMALL(tblAttendance[Rank Key],$I46),tblAttendance[Rank Key],0)),"-") -> 0.62857143 | N46: =IFERROR(INDEX(tblAttendance[Status],MATCH(SMALL(tblAttendance[Rank Key],$I46),tblAttendance[Rank Key],0)),"-") -> Shortage
B47: 4 | C47: =IFERROR(INDEX(tblAttendance[Student Name],MATCH(LARGE(tblAttendance[Rank Key],$B47),tblAttendance[Rank Key],0)),"-") -> Garima Kumar | D47: =IFERROR(INDEX(tblAttendance[Branch],MATCH(LARGE(tblAttendance[Rank Key],$B47),tblAttendance[Rank Key],0)),"-") -> IT | E47: =IFERROR(INDEX(tblAttendance[Semester],MATCH(LARGE(tblAttendance[Rank Key],$B47),tblAttendance[Rank Key],0)),"-") -> 1 | F47: =IFERROR(INDEX(tblAttendance[Attendance %],MATCH(LARGE(tblAttendance[Rank Key],$B47),tblAttendance[Rank Key],0)),"-") -> 0.98843931 | G47: =IFERROR(INDEX(tblAttendance[Status],MATCH(LARGE(tblAttendance[Rank Key],$B47),tblAttendance[Rank Key],0)),"-") -> Excellent | I47: 4 | J47: =IFERROR(INDEX(tblAttendance[Student Name],MATCH(SMALL(tblAttendance[Rank Key],$I47),tblAttendance[Rank Key],0)),"-") -> Aditi Agarwal | K47: =IFERROR(INDEX(tblAttendance[Branch],MATCH(SMALL(tblAttendance[Rank Key],$I47),tblAttendance[Rank Key],0)),"-") -> ME | L47: =IFERROR(INDEX(tblAttendance[Semester],MATCH(SMALL(tblAttendance[Rank Key],$I47),tblAttendance[Rank Key],0)),"-") -> 4 | M47: =IFERROR(INDEX(tblAttendance[Attendance %],MATCH(SMALL(tblAttendance[Rank Key],$I47),tblAttendance[Rank Key],0)),"-") -> 0.63529412 | N47: =IFERROR(INDEX(tblAttendance[Status],MATCH(SMALL(tblAttendance[Rank Key],$I47),tblAttendance[Rank Key],0)),"-") -> Shortage
B48: 5 | C48: =IFERROR(INDEX(tblAttendance[Student Name],MATCH(LARGE(tblAttendance[Rank Key],$B48),tblAttendance[Rank Key],0)),"-") -> Vivaan Shah | D48: =IFERROR(INDEX(tblAttendance[Branch],MATCH(LARGE(tblAttendance[Rank Key],$B48),tblAttendance[Rank Key],0)),"-") -> ME | E48: =IFERROR(INDEX(tblAttendance[Semester],MATCH(LARGE(tblAttendance[Rank Key],$B48),tblAttendance[Rank Key],0)),"-") -> 6 | F48: =IFERROR(INDEX(tblAttendance[Attendance %],MATCH(LARGE(tblAttendance[Rank Key],$B48),tblAttendance[Rank Key],0)),"-") -> 0.98823529 | G48: =IFERROR(INDEX(tblAttendance[Status],MATCH(LARGE(tblAttendance[Rank Key],$B48),tblAttendance[Rank Key],0)),"-") -> Excellent | I48: 5 | J48: =IFERROR(INDEX(tblAttendance[Student Name],MATCH(SMALL(tblAttendance[Rank Key],$I48),tblAttendance[Rank Key],0)),"-") -> Vaishnavi Ansari | K48: =IFERROR(INDEX(tblAttendance[Branch],MATCH(SMALL(tblAttendance[Rank Key],$I48),tblAttendance[Rank Key],0)),"-") -> IT | L48: =IFERROR(INDEX(tblAttendance[Semester],MATCH(SMALL(tblAttendance[Rank Key],$I48),tblAttendance[Rank Key],0)),"-") -> 6 | M48: =IFERROR(INDEX(tblAttendance[Attendance %],MATCH(SMALL(tblAttendance[Rank Key],$I48),tblAttendance[Rank Key],0)),"-") -> 0.64210526 | N48: =IFERROR(INDEX(tblAttendance[Status],MATCH(SMALL(tblAttendance[Rank Key],$I48),tblAttendance[Rank Key],0)),"-") -> Shortage
B49: 6 | C49: =IFERROR(INDEX(tblAttendance[Student Name],MATCH(LARGE(tblAttendance[Rank Key],$B49),tblAttendance[Rank Key],0)),"-") -> Devansh Jain | D49: =IFERROR(INDEX(tblAttendance[Branch],MATCH(LARGE(tblAttendance[Rank Key],$B49),tblAttendance[Rank Key],0)),"-") -> ECE | E49: =IFERROR(INDEX(tblAttendance[Semester],MATCH(LARGE(tblAttendance[Rank Key],$B49),tblAttendance[Rank Key],0)),"-") -> 5 | F49: =IFERROR(INDEX(tblAttendance[Attendance %],MATCH(LARGE(tblAttendance[Rank Key],$B49),tblAttendance[Rank Key],0)),"-") -> 0.98809524 | G49: =IFERROR(INDEX(tblAttendance[Status],MATCH(LARGE(tblAttendance[Rank Key],$B49),tblAttendance[Rank Key],0)),"-") -> Excellent | I49: 6 | J49: =IFERROR(INDEX(tblAttendance[Student Name],MATCH(SMALL(tblAttendance[Rank Key],$I49),tblAttendance[Rank Key],0)),"-") -> Varun Iyer | K49: =IFERROR(INDEX(tblAttendance[Branch],MATCH(SMALL(tblAttendance[Rank Key],$I49),tblAttendance[Rank Key],0)),"-") -> CE | L49: =IFERROR(INDEX(tblAttendance[Semester],MATCH(SMALL(tblAttendance[Rank Key],$I49),tblAttendance[Rank Key],0)),"-") -> 3 | M49: =IFERROR(INDEX(tblAttendance[Attendance %],MATCH(SMALL(tblAttendance[Rank Key],$I49),tblAttendance[Rank Key],0)),"-") -> 0.65359477 | N49: =IFERROR(INDEX(tblAttendance[Status],MATCH(SMALL(tblAttendance[Rank Key],$I49),tblAttendance[Rank Key],0)),"-") -> Shortage
B50: 7 | C50: =IFERROR(INDEX(tblAttendance[Student Name],MATCH(LARGE(tblAttendance[Rank Key],$B50),tblAttendance[Rank Key],0)),"-") -> Jhanvi Ansari | D50: =IFERROR(INDEX(tblAttendance[Branch],MATCH(LARGE(tblAttendance[Rank Key],$B50),tblAttendance[Rank Key],0)),"-") -> CSE | E50: =IFERROR(INDEX(tblAttendance[Semester],MATCH(LARGE(tblAttendance[Rank Key],$B50),tblAttendance[Rank Key],0)),"-") -> 6 | F50: =IFERROR(INDEX(tblAttendance[Attendance %],MATCH(LARGE(tblAttendance[Rank Key],$B50),tblAttendance[Rank Key],0)),"-") -> 0.9875 | G50: =IFERROR(INDEX(tblAttendance[Status],MATCH(LARGE(tblAttendance[Rank Key],$B50),tblAttendance[Rank Key],0)),"-") -> Excellent | I50: 7 | J50: =IFERROR(INDEX(tblAttendance[Student Name],MATCH(SMALL(tblAttendance[Rank Key],$I50),tblAttendance[Rank Key],0)),"-") -> Srishti Garg | K50: =IFERROR(INDEX(tblAttendance[Branch],MATCH(SMALL(tblAttendance[Rank Key],$I50),tblAttendance[Rank Key],0)),"-") -> ECE | L50: =IFERROR(INDEX(tblAttendance[Semester],MATCH(SMALL(tblAttendance[Rank Key],$I50),tblAttendance[Rank Key],0)),"-") -> 5 | M50: =IFERROR(INDEX(tblAttendance[Attendance %],MATCH(SMALL(tblAttendance[Rank Key],$I50),tblAttendance[Rank Key],0)),"-") -> 0.67955801 | N50: =IFERROR(INDEX(tblAttendance[Status],MATCH(SMALL(tblAttendance[Rank Key],$I50),tblAttendance[Rank Key],0)),"-") -> Shortage
B51: 8 | C51: =IFERROR(INDEX(tblAttendance[Student Name],MATCH(LARGE(tblAttendance[Rank Key],$B51),tblAttendance[Rank Key],0)),"-") -> Tanya Bhatt | D51: =IFERROR(INDEX(tblAttendance[Branch],MATCH(LARGE(tblAttendance[Rank Key],$B51),tblAttendance[Rank Key],0)),"-") -> CSE | E51: =IFERROR(INDEX(tblAttendance[Semester],MATCH(LARGE(tblAttendance[Rank Key],$B51),tblAttendance[Rank Key],0)),"-") -> 7 | F51: =IFERROR(INDEX(tblAttendance[Attendance %],MATCH(LARGE(tblAttendance[Rank Key],$B51),tblAttendance[Rank Key],0)),"-") -> 0.98734177 | G51: =IFERROR(INDEX(tblAttendance[Status],MATCH(LARGE(tblAttendance[Rank Key],$B51),tblAttendance[Rank Key],0)),"-") -> Excellent | I51: 8 | J51: =IFERROR(INDEX(tblAttendance[Student Name],MATCH(SMALL(tblAttendance[Rank Key],$I51),tblAttendance[Rank Key],0)),"-") -> Mayank Agarwal | K51: =IFERROR(INDEX(tblAttendance[Branch],MATCH(SMALL(tblAttendance[Rank Key],$I51),tblAttendance[Rank Key],0)),"-") -> CE | L51: =IFERROR(INDEX(tblAttendance[Semester],MATCH(SMALL(tblAttendance[Rank Key],$I51),tblAttendance[Rank Key],0)),"-") -> 6 | M51: =IFERROR(INDEX(tblAttendance[Attendance %],MATCH(SMALL(tblAttendance[Rank Key],$I51),tblAttendance[Rank Key],0)),"-") -> 0.68589744 | N51: =IFERROR(INDEX(tblAttendance[Status],MATCH(SMALL(tblAttendance[Rank Key],$I51),tblAttendance[Rank Key],0)),"-") -> Shortage
B52: 9 | C52: =IFERROR(INDEX(tblAttendance[Student Name],MATCH(LARGE(tblAttendance[Rank Key],$B52),tblAttendance[Rank Key],0)),"-") -> Yash Banerjee | D52: =IFERROR(INDEX(tblAttendance[Branch],MATCH(LARGE(tblAttendance[Rank Key],$B52),tblAttendance[Rank Key],0)),"-") -> ME | E52: =IFERROR(INDEX(tblAttendance[Semester],MATCH(LARGE(tblAttendance[Rank Key],$B52),tblAttendance[Rank Key],0)),"-") -> 3 | F52: =IFERROR(INDEX(tblAttendance[Attendance %],MATCH(LARGE(tblAttendance[Rank Key],$B52),tblAttendance[Rank Key],0)),"-") -> 0.98709677 | G52: =IFERROR(INDEX(tblAttendance[Status],MATCH(LARGE(tblAttendance[Rank Key],$B52),tblAttendance[Rank Key],0)),"-") -> Excellent | I52: 9 | J52: =IFERROR(INDEX(tblAttendance[Student Name],MATCH(SMALL(tblAttendance[Rank Key],$I52),tblAttendance[Rank Key],0)),"-") -> Deepak Khan | K52: =IFERROR(INDEX(tblAttendance[Branch],MATCH(SMALL(tblAttendance[Rank Key],$I52),tblAttendance[Rank Key],0)),"-") -> ME | L52: =IFERROR(INDEX(tblAttendance[Semester],MATCH(SMALL(tblAttendance[Rank Key],$I52),tblAttendance[Rank Key],0)),"-") -> 7 | M52: =IFERROR(INDEX(tblAttendance[Attendance %],MATCH(SMALL(tblAttendance[Rank Key],$I52),tblAttendance[Rank Key],0)),"-") -> 0.68639053 | N52: =IFERROR(INDEX(tblAttendance[Status],MATCH(SMALL(tblAttendance[Rank Key],$I52),tblAttendance[Rank Key],0)),"-") -> Shortage
B53: 10 | C53: =IFERROR(INDEX(tblAttendance[Student Name],MATCH(LARGE(tblAttendance[Rank Key],$B53),tblAttendance[Rank Key],0)),"-") -> Rajat Tiwari | D53: =IFERROR(INDEX(tblAttendance[Branch],MATCH(LARGE(tblAttendance[Rank Key],$B53),tblAttendance[Rank Key],0)),"-") -> IT | E53: =IFERROR(INDEX(tblAttendance[Semester],MATCH(LARGE(tblAttendance[Rank Key],$B53),tblAttendance[Rank Key],0)),"-") -> 3 | F53: =IFERROR(INDEX(tblAttendance[Attendance %],MATCH(LARGE(tblAttendance[Rank Key],$B53),tblAttendance[Rank Key],0)),"-") -> 0.98684211 | G53: =IFERROR(INDEX(tblAttendance[Status],MATCH(LARGE(tblAttendance[Rank Key],$B53),tblAttendance[Rank Key],0)),"-") -> Excellent | I53: 10 | J53: =IFERROR(INDEX(tblAttendance[Student Name],MATCH(SMALL(tblAttendance[Rank Key],$I53),tblAttendance[Rank Key],0)),"-") -> Radhika Kumar | K53: =IFERROR(INDEX(tblAttendance[Branch],MATCH(SMALL(tblAttendance[Rank Key],$I53),tblAttendance[Rank Key],0)),"-") -> IT | L53: =IFERROR(INDEX(tblAttendance[Semester],MATCH(SMALL(tblAttendance[Rank Key],$I53),tblAttendance[Rank Key],0)),"-") -> 7 | M53: =IFERROR(INDEX(tblAttendance[Attendance %],MATCH(SMALL(tblAttendance[Rank Key],$I53),tblAttendance[Rank Key],0)),"-") -> 0.68674699 | N53: =IFERROR(INDEX(tblAttendance[Status],MATCH(SMALL(tblAttendance[Rank Key],$I53),tblAttendance[Rank Key],0)),"-") -> Shortage
B55: Status: Excellent ≥ 90%, Good ≥ 80%, Satisfactory ≥ 75%, Shortage < 75% (thresholds editable on Lists). Scatter plots every record regardless of filters.

Sheet Faculty Dashboard
B1: Faculty Performance Analytics
B2: Feedback, results, research output and composite performance score | source: tblFaculty
B3: « Overview | D3: Students | E3: Attendance | F3: Faculty | G3: Placements | I3: Courses | K3: Instructions | M3: Data »
B5: Branch | C5: All | D5: Year | E5: All | I5: Choose 'All' to clear a filter. Score = feedback 40 + pass rate 30 + research 20 + experience 10 (weights editable on Lists).
B7: FACULTY EVALUATED | E7: AVG STUDENT FEEDBACK | I7: AVG PERFORMANCE SCORE | L7: RESEARCH PAPERS
B8: =COUNTIFS(tblFaculty[Department],cFa_B,tblFaculty[Year],cFa_Y) -> 30 | E8: =IFERROR(AVERAGEIFS(tblFaculty[Student Feedback],tblFaculty[Department],cFa_B,tblFaculty[Year],cFa_Y),0) -> 4.0426667 | I8: =IFERROR(AVERAGEIFS(tblFaculty[Performance Score],tblFaculty[Department],cFa_B,tblFaculty[Year],cFa_Y),0) -> 76.45 | L8: =SUMIFS(tblFaculty[Research Papers],tblFaculty[Department],cFa_B,tblFaculty[Year],cFa_Y) -> 188
B10: ="Outstanding: "&COUNTIFS(tblFaculty[Department],cFa_B,tblFaculty[Year],cFa_Y,tblFaculty[Rating],"Outstanding")&" | Needs improvement: "&COUNTIFS(tblFaculty[Department],cFa_B,tblFaculty[Year],cFa_Y,tblFaculty[Rating],"Needs Improvement") -> Outstanding: 9 | Needs improvement: 4 | E10: ="Out of 5.00" -> Out of 5.00 | I10: ="Avg student pass rate: "&TEXT(IFERROR(AVERAGEIFS(tblFaculty[Student Pass Rate],tblFaculty[Department],cFa_B,tblFaculty[Year],cFa_Y),0),"0.0%") -> Avg student pass rate: 91.7% | L10: ="Avg experience: "&TEXT(IFERROR(AVERAGEIFS(tblFaculty[Experience Yrs],tblFaculty[Department],cFa_B,tblFaculty[Year],cFa_Y),0),"0.0")&" years" -> Avg experience: 11.6 years
B42: ▲ TOP 10 FACULTY - PERFORMANCE SCORE | I42: ▼ BOTTOM 10 FACULTY - PERFORMANCE SCORE
B43: # | C43: Faculty | D43: Dept | E43: Feedback | F43: Papers | G43: Score | I43: # | J43: Faculty | K43: Dept | L43: Feedback | M43: Papers | N43: Score
B44: 1 | C44: =IFERROR(INDEX(tblFaculty[Faculty Name],MATCH(LARGE(tblFaculty[Rank Key],$B44),tblFaculty[Rank Key],0)),"-") -> Dr. Manoj Yadav | D44: =IFERROR(INDEX(tblFaculty[Department],MATCH(LARGE(tblFaculty[Rank Key],$B44),tblFaculty[Rank Key],0)),"-") -> IT | E44: =IFERROR(INDEX(tblFaculty[Student Feedback],MATCH(LARGE(tblFaculty[Rank Key],$B44),tblFaculty[Rank Key],0)),"-") -> 4.48 | F44: =IFERROR(INDEX(tblFaculty[Research Papers],MATCH(LARGE(tblFaculty[Rank Key],$B44),tblFaculty[Rank Key],0)),"-") -> 17 | G44: =IFERROR(INDEX(tblFaculty[Performance Score],MATCH(LARGE(tblFaculty[Rank Key],$B44),tblFaculty[Rank Key],0)),"-") -> 93.6 | I44: 1 | J44: =IFERROR(INDEX(tblFaculty[Faculty Name],MATCH(SMALL(tblFaculty[Rank Key],$I44),tblFaculty[Rank Key],0)),"-") -> Mr. Rekha Chatterjee | K44: =IFERROR(INDEX(tblFaculty[Department],MATCH(SMALL(tblFaculty[Rank Key],$I44),tblFaculty[Rank Key],0)),"-") -> CE | L44: =IFERROR(INDEX(tblFaculty[Student Feedback],MATCH(SMALL(tblFaculty[Rank Key],$I44),tblFaculty[Rank Key],0)),"-") -> 3.58 | M44: =IFERROR(INDEX(tblFaculty[Research Papers],MATCH(SMALL(tblFaculty[Rank Key],$I44),tblFaculty[Rank Key],0)),"-") -> 0 | N44: =IFERROR(INDEX(tblFaculty[Performance Score],MATCH(SMALL(tblFaculty[Rank Key],$I44),tblFaculty[Rank Key],0)),"-") -> 56.1
B45: 2 | C45: =IFERROR(INDEX(tblFaculty[Faculty Name],MATCH(LARGE(tblFaculty[Rank Key],$B45),tblFaculty[Rank Key],0)),"-") -> Dr. Usha Shah | D45: =IFERROR(INDEX(tblFaculty[Department],MATCH(LARGE(tblFaculty[Rank Key],$B45),tblFaculty[Rank Key],0)),"-") -> ME | E45: =IFERROR(INDEX(tblFaculty[Student Feedback],MATCH(LARGE(tblFaculty[Rank Key],$B45),tblFaculty[Rank Key],0)),"-") -> 4.71 | F45: =IFERROR(INDEX(tblFaculty[Research Papers],MATCH(LARGE(tblFaculty[Rank Key],$B45),tblFaculty[Rank Key],0)),"-") -> 9 | G45: =IFERROR(INDEX(tblFaculty[Performance Score],MATCH(LARGE(tblFaculty[Rank Key],$B45),tblFaculty[Rank Key],0)),"-") -> 92 | I45: 2 | J45: =IFERROR(INDEX(tblFaculty[Faculty Name],MATCH(SMALL(tblFaculty[Rank Key],$I45),tblFaculty[Rank Key],0)),"-") -> Mr. Neeta Thakur | K45: =IFERROR(INDEX(tblFaculty[Department],MATCH(SMALL(tblFaculty[Rank Key],$I45),tblFaculty[Rank Key],0)),"-") -> CSE | L45: =IFERROR(INDEX(tblFaculty[Student Feedback],MATCH(SMALL(tblFaculty[Rank Key],$I45),tblFaculty[Rank Key],0)),"-") -> 3.53 | M45: =IFERROR(INDEX(tblFaculty[Research Papers],MATCH(SMALL(tblFaculty[Rank Key],$I45),tblFaculty[Rank Key],0)),"-") -> 2 | N45: =IFERROR(INDEX(tblFaculty[Performance Score],MATCH(SMALL(tblFaculty[Rank Key],$I45),tblFaculty[Rank Key],0)),"-") -> 60.9
B46: 3 | C46: =IFERROR(INDEX(tblFaculty[Faculty Name],MATCH(LARGE(tblFaculty[Rank Key],$B46),tblFaculty[Rank Key],0)),"-") -> Dr. Pradeep Srivastava | D46: =IFERROR(INDEX(tblFaculty[Department],MATCH(LARGE(tblFaculty[Rank Key],$B46),tblFaculty[Rank Key],0)),"-") -> CE | E46: =IFERROR(INDEX(tblFaculty[Student Feedback],MATCH(LARGE(tblFaculty[Rank Key],$B46),tblFaculty[Rank Key],0)),"-") -> 4.4 | F46: =IFERROR(INDEX(tblFaculty[Research Papers],MATCH(LARGE(tblFaculty[Rank Key],$B46),tblFaculty[Rank Key],0)),"-") -> 11 | G46: =IFERROR(INDEX(tblFaculty[Performance Score],MATCH(LARGE(tblFaculty[Rank Key],$B46),tblFaculty[Rank Key],0)),"-") -> 91.5 | I46: 3 | J46: =IFERROR(INDEX(tblFaculty[Faculty Name],MATCH(SMALL(tblFaculty[Rank Key],$I46),tblFaculty[Rank Key],0)),"-") -> Prof. Vinod Thakur | K46: =IFERROR(INDEX(tblFaculty[Department],MATCH(SMALL(tblFaculty[Rank Key],$I46),tblFaculty[Rank Key],0)),"-") -> CSE | L46: =IFERROR(INDEX(tblFaculty[Student Feedback],MATCH(SMALL(tblFaculty[Rank Key],$I46),tblFaculty[Rank Key],0)),"-") -> 3.99 | M46: =IFERROR(INDEX(tblFaculty[Research Papers],MATCH(SMALL(tblFaculty[Rank Key],$I46),tblFaculty[Rank Key],0)),"-") -> 0 | N46: =IFERROR(INDEX(tblFaculty[Performance Score],MATCH(SMALL(tblFaculty[Rank Key],$I46),tblFaculty[Rank Key],0)),"-") -> 62
B47: 4 | C47: =IFERROR(INDEX(tblFaculty[Faculty Name],MATCH(LARGE(tblFaculty[Rank Key],$B47),tblFaculty[Rank Key],0)),"-") -> Dr. Arvind Sharma | D47: =IFERROR(INDEX(tblFaculty[Department],MATCH(LARGE(tblFaculty[Rank Key],$B47),tblFaculty[Rank Key],0)),"-") -> CE | E47: =IFERROR(INDEX(tblFaculty[Student Feedback],MATCH(LARGE(tblFaculty[Rank Key],$B47),tblFaculty[Rank Key],0)),"-") -> 4.13 | F47: =IFERROR(INDEX(tblFaculty[Research Papers],MATCH(LARGE(tblFaculty[Rank Key],$B47),tblFaculty[Rank Key],0)),"-") -> 9 | G47: =IFERROR(INDEX(tblFaculty[Performance Score],MATCH(LARGE(tblFaculty[Rank Key],$B47),tblFaculty[Rank Key],0)),"-") -> 90.5 | I47: 4 | J47: =IFERROR(INDEX(tblFaculty[Faculty Name],MATCH(SMALL(tblFaculty[Rank Key],$I47),tblFaculty[Rank Key],0)),"-") -> Prof. Sanjay Ansari | K47: =IFERROR(INDEX(tblFaculty[Department],MATCH(SMALL(tblFaculty[Rank Key],$I47),tblFaculty[Rank Key],0)),"-") -> IT | L47: =IFERROR(INDEX(tblFaculty[Student Feedback],MATCH(SMALL(tblFaculty[Rank Key],$I47),tblFaculty[Rank Key],0)),"-") -> 3.94 | M47: =IFERROR(INDEX(tblFaculty[Research Papers],MATCH(SMALL(tblFaculty[Rank Key],$I47),tblFaculty[Rank Key],0)),"-") -> 0 | N47: =IFERROR(INDEX(tblFaculty[Performance Score],MATCH(SMALL(tblFaculty[Rank Key],$I47),tblFaculty[Rank Key],0)),"-") -> 63.7
B48: 5 | C48: =IFERROR(INDEX(tblFaculty[Faculty Name],MATCH(LARGE(tblFaculty[Rank Key],$B48),tblFaculty[Rank Key],0)),"-") -> Dr. Madhu Ansari | D48: =IFERROR(INDEX(tblFaculty[Department],MATCH(LARGE(tblFaculty[Rank Key],$B48),tblFaculty[Rank Key],0)),"-") -> ME | E48: =IFERROR(INDEX(tblFaculty[Student Feedback],MATCH(LARGE(tblFaculty[Rank Key],$B48),tblFaculty[Rank Key],0)),"-") -> 4.3 | F48: =IFERROR(INDEX(tblFaculty[Research Papers],MATCH(LARGE(tblFaculty[Rank Key],$B48),tblFaculty[Rank Key],0)),"-") -> 10 | G48: =IFERROR(INDEX(tblFaculty[Performance Score],MATCH(LARGE(tblFaculty[Rank Key],$B48),tblFaculty[Rank Key],0)),"-") -> 90.2 | I48: 5 | J48: =IFERROR(INDEX(tblFaculty[Faculty Name],MATCH(SMALL(tblFaculty[Rank Key],$I48),tblFaculty[Rank Key],0)),"-") -> Prof. Renu Reddy | K48: =IFERROR(INDEX(tblFaculty[Department],MATCH(SMALL(tblFaculty[Rank Key],$I48),tblFaculty[Rank Key],0)),"-") -> CSE | L48: =IFERROR(INDEX(tblFaculty[Student Feedback],MATCH(SMALL(tblFaculty[Rank Key],$I48),tblFaculty[Rank Key],0)),"-") -> 3.95 | M48: =IFERROR(INDEX(tblFaculty[Research Papers],MATCH(SMALL(tblFaculty[Rank Key],$I48),tblFaculty[Rank Key],0)),"-") -> 1 | N48: =IFERROR(INDEX(tblFaculty[Performance Score],MATCH(SMALL(tblFaculty[Rank Key],$I48),tblFaculty[Rank Key],0)),"-") -> 66.8
B49: 6 | C49: =IFERROR(INDEX(tblFaculty[Faculty Name],MATCH(LARGE(tblFaculty[Rank Key],$B49),tblFaculty[Rank Key],0)),"-") -> Dr. Dinesh Gupta | D49: =IFERROR(INDEX(tblFaculty[Department],MATCH(LARGE(tblFaculty[Rank Key],$B49),tblFaculty[Rank Key],0)),"-") -> ME | E49: =IFERROR(INDEX(tblFaculty[Student Feedback],MATCH(LARGE(tblFaculty[Rank Key],$B49),tblFaculty[Rank Key],0)),"-") -> 3.97 | F49: =IFERROR(INDEX(tblFaculty[Research Papers],MATCH(LARGE(tblFaculty[Rank Key],$B49),tblFaculty[Rank Key],0)),"-") -> 19 | G49: =IFERROR(INDEX(tblFaculty[Performance Score],MATCH(LARGE(tblFaculty[Rank Key],$B49),tblFaculty[Rank Key],0)),"-") -> 88.3 | I49: 6 | J49: =IFERROR(INDEX(tblFaculty[Faculty Name],MATCH(SMALL(tblFaculty[Rank Key],$I49),tblFaculty[Rank Key],0)),"-") -> Prof. Ramesh Saxena | K49: =IFERROR(INDEX(tblFaculty[Department],MATCH(SMALL(tblFaculty[Rank Key],$I49),tblFaculty[Rank Key],0)),"-") -> CE | L49: =IFERROR(INDEX(tblFaculty[Student Feedback],MATCH(SMALL(tblFaculty[Rank Key],$I49),tblFaculty[Rank Key],0)),"-") -> 3.93 | M49: =IFERROR(INDEX(tblFaculty[Research Papers],MATCH(SMALL(tblFaculty[Rank Key],$I49),tblFaculty[Rank Key],0)),"-") -> 2 | N49: =IFERROR(INDEX(tblFaculty[Performance Score],MATCH(SMALL(tblFaculty[Rank Key],$I49),tblFaculty[Rank Key],0)),"-") -> 67.5
B50: 7 | C50: =IFERROR(INDEX(tblFaculty[Faculty Name],MATCH(LARGE(tblFaculty[Rank Key],$B50),tblFaculty[Rank Key],0)),"-") -> Dr. Sunil Sharma | D50: =IFERROR(INDEX(tblFaculty[Department],MATCH(LARGE(tblFaculty[Rank Key],$B50),tblFaculty[Rank Key],0)),"-") -> CE | E50: =IFERROR(INDEX(tblFaculty[Student Feedback],MATCH(LARGE(tblFaculty[Rank Key],$B50),tblFaculty[Rank Key],0)),"-") -> 3.99 | F50: =IFERROR(INDEX(tblFaculty[Research Papers],MATCH(LARGE(tblFaculty[Rank Key],$B50),tblFaculty[Rank Key],0)),"-") -> 11 | G50: =IFERROR(INDEX(tblFaculty[Performance Score],MATCH(LARGE(tblFaculty[Rank Key],$B50),tblFaculty[Rank Key],0)),"-") -> 86.9 | I50: 7 | J50: =IFERROR(INDEX(tblFaculty[Faculty Name],MATCH(SMALL(tblFaculty[Rank Key],$I50),tblFaculty[Rank Key],0)),"-") -> Prof. Sunita Banerjee | K50: =IFERROR(INDEX(tblFaculty[Department],MATCH(SMALL(tblFaculty[Rank Key],$I50),tblFaculty[Rank Key],0)),"-") -> IT | L50: =IFERROR(INDEX(tblFaculty[Student Feedback],MATCH(SMALL(tblFaculty[Rank Key],$I50),tblFaculty[Rank Key],0)),"-") -> 4.51 | M50: =IFERROR(INDEX(tblFaculty[Research Papers],MATCH(SMALL(tblFaculty[Rank Key],$I50),tblFaculty[Rank Key],0)),"-") -> 0 | N50: =IFERROR(INDEX(tblFaculty[Performance Score],MATCH(SMALL(tblFaculty[Rank Key],$I50),tblFaculty[Rank Key],0)),"-") -> 68.1
B51: 8 | C51: =IFERROR(INDEX(tblFaculty[Faculty Name],MATCH(LARGE(tblFaculty[Rank Key],$B51),tblFaculty[Rank Key],0)),"-") -> Dr. Rakesh Banerjee | D51: =IFERROR(INDEX(tblFaculty[Department],MATCH(LARGE(tblFaculty[Rank Key],$B51),tblFaculty[Rank Key],0)),"-") -> IT | E51: =IFERROR(INDEX(tblFaculty[Student Feedback],MATCH(LARGE(tblFaculty[Rank Key],$B51),tblFaculty[Rank Key],0)),"-") -> 3.82 | F51: =IFERROR(INDEX(tblFaculty[Research Papers],MATCH(LARGE(tblFaculty[Rank Key],$B51),tblFaculty[Rank Key],0)),"-") -> 12 | G51: =IFERROR(INDEX(tblFaculty[Performance Score],MATCH(LARGE(tblFaculty[Rank Key],$B51),tblFaculty[Rank Key],0)),"-") -> 86.2 | I51: 8 | J51: =IFERROR(INDEX(tblFaculty[Faculty Name],MATCH(SMALL(tblFaculty[Rank Key],$I51),tblFaculty[Rank Key],0)),"-") -> Mr. Nisha Dubey | K51: =IFERROR(INDEX(tblFaculty[Department],MATCH(SMALL(tblFaculty[Rank Key],$I51),tblFaculty[Rank Key],0)),"-") -> CE | L51: =IFERROR(INDEX(tblFaculty[Student Feedback],MATCH(SMALL(tblFaculty[Rank Key],$I51),tblFaculty[Rank Key],0)),"-") -> 4.55 | M51: =IFERROR(INDEX(tblFaculty[Research Papers],MATCH(SMALL(tblFaculty[Rank Key],$I51),tblFaculty[Rank Key],0)),"-") -> 2 | N51: =IFERROR(INDEX(tblFaculty[Performance Score],MATCH(SMALL(tblFaculty[Rank Key],$I51),tblFaculty[Rank Key],0)),"-") -> 68.1
B52: 9 | C52: =IFERROR(INDEX(tblFaculty[Faculty Name],MATCH(LARGE(tblFaculty[Rank Key],$B52),tblFaculty[Rank Key],0)),"-") -> Dr. Mamta Reddy | D52: =IFERROR(INDEX(tblFaculty[Department],MATCH(LARGE(tblFaculty[Rank Key],$B52),tblFaculty[Rank Key],0)),"-") -> ECE | E52: =IFERROR(INDEX(tblFaculty[Student Feedback],MATCH(LARGE(tblFaculty[Rank Key],$B52),tblFaculty[Rank Key],0)),"-") -> 4.11 | F52: =IFERROR(INDEX(tblFaculty[Research Papers],MATCH(LARGE(tblFaculty[Rank Key],$B52),tblFaculty[Rank Key],0)),"-") -> 8 | G52: =IFERROR(INDEX(tblFaculty[Performance Score],MATCH(LARGE(tblFaculty[Rank Key],$B52),tblFaculty[Rank Key],0)),"-") -> 86 | I52: 9 | J52: =IFERROR(INDEX(tblFaculty[Faculty Name],MATCH(SMALL(tblFaculty[Rank Key],$I52),tblFaculty[Rank Key],0)),"-") -> Prof. Alok Goel | K52: =IFERROR(INDEX(tblFaculty[Department],MATCH(SMALL(tblFaculty[Rank Key],$I52),tblFaculty[Rank Key],0)),"-") -> CSE | L52: =IFERROR(INDEX(tblFaculty[Student Feedback],MATCH(SMALL(tblFaculty[Rank Key],$I52),tblFaculty[Rank Key],0)),"-") -> 4 | M52: =IFERROR(INDEX(tblFaculty[Research Papers],MATCH(SMALL(tblFaculty[Rank Key],$I52),tblFaculty[Rank Key],0)),"-") -> 4 | N52: =IFERROR(INDEX(tblFaculty[Performance Score],MATCH(SMALL(tblFaculty[Rank Key],$I52),tblFaculty[Rank Key],0)),"-") -> 68.4
B53: 10 | C53: =IFERROR(INDEX(tblFaculty[Faculty Name],MATCH(LARGE(tblFaculty[Rank Key],$B53),tblFaculty[Rank Key],0)),"-") -> Dr. Poonam Agarwal | D53: =IFERROR(INDEX(tblFaculty[Department],MATCH(LARGE(tblFaculty[Rank Key],$B53),tblFaculty[Rank Key],0)),"-") -> ME | E53: =IFERROR(INDEX(tblFaculty[Student Feedback],MATCH(LARGE(tblFaculty[Rank Key],$B53),tblFaculty[Rank Key],0)),"-") -> 3.76 | F53: =IFERROR(INDEX(tblFaculty[Research Papers],MATCH(LARGE(tblFaculty[Rank Key],$B53),tblFaculty[Rank Key],0)),"-") -> 10 | G53: =IFERROR(INDEX(tblFaculty[Performance Score],MATCH(LARGE(tblFaculty[Rank Key],$B53),tblFaculty[Rank Key],0)),"-") -> 84.2 | I53: 10 | J53: =IFERROR(INDEX(tblFaculty[Faculty Name],MATCH(SMALL(tblFaculty[Rank Key],$I53),tblFaculty[Rank Key],0)),"-") -> Prof. Shalini Patel | K53: =IFERROR(INDEX(tblFaculty[Department],MATCH(SMALL(tblFaculty[Rank Key],$I53),tblFaculty[Rank Key],0)),"-") -> ECE | L53: =IFERROR(INDEX(tblFaculty[Student Feedback],MATCH(SMALL(tblFaculty[Rank Key],$I53),tblFaculty[Rank Key],0)),"-") -> 4.64 | M53: =IFERROR(INDEX(tblFaculty[Research Papers],MATCH(SMALL(tblFaculty[Rank Key],$I53),tblFaculty[Rank Key],0)),"-") -> 1 | N53: =IFERROR(INDEX(tblFaculty[Performance Score],MATCH(SMALL(tblFaculty[Rank Key],$I53),tblFaculty[Rank Key],0)),"-") -> 68.6
B55: Rating bands: Outstanding ≥ 85, Very Good ≥ 75, Good ≥ 65, otherwise Needs Improvement. Ranks respect the active filters.

Sheet Placement Dashboard
B1: Placement Analytics
B2: Placement rate, packages, sectors and recruiters | source: tblPlacements
B3: « Overview | D3: Students | E3: Attendance | F3: Faculty | G3: Placements | I3: Courses | K3: Instructions | M3: Data »
B5: Branch | C5: All | D5: Year | E5: All | I5: Choose 'All' to clear a filter. Packages are in Lakhs Per Annum (LPA). Branch-comparison charts ignore the Branch filter.
B7: STUDENTS REGISTERED | E7: PLACEMENT RATE | I7: AVERAGE PACKAGE (LPA) | L7: HIGHEST PACKAGE (LPA)
B8: =COUNTIFS(tblPlacements[Branch],cPl_B,tblPlacements[Year],cPl_Y) -> 150 | E8: =IFERROR(COUNTIFS(tblPlacements[Branch],cPl_B,tblPlacements[Year],cPl_Y,tblPlacements[Status],"Placed")/COUNTIFS(tblPlacements[Branch],cPl_B,tblPlacements[Year],cPl_Y),0) -> 0.76 | I8: =IFERROR(AVERAGEIFS(tblPlacements[Package LPA],tblPlacements[Branch],cPl_B,tblPlacements[Year],cPl_Y,tblPlacements[Status],"Placed"),0) -> 9.6482456 | L8: =_xlfn.MAXIFS(tblPlacements[Package LPA],tblPlacements[Branch],cPl_B,tblPlacements[Year],cPl_Y) -> 44.4
B10: ="Placed: "&COUNTIFS(tblPlacements[Branch],cPl_B,tblPlacements[Year],cPl_Y,tblPlacements[Status],"Placed")&" | Not placed: "&(COUNTIFS(tblPlacements[Branch],cPl_B,tblPlacements[Year],cPl_Y)-COUNTIFS(tblPlacements[Branch],cPl_B,tblPlacements[Year],cPl_Y,tblPlacements[Status],"Placed")) -> Placed: 114 | Not placed: 36 | E10: ="Placed ÷ registered" -> Placed ÷ registered | I10: ="Avg CGPA of placed: "&TEXT(IFERROR(AVERAGEIFS(tblPlacements[CGPA],tblPlacements[Branch],cPl_B,tblPlacements[Year],cPl_Y,tblPlacements[Status],"Placed"),0),"0.00") -> Avg CGPA of placed: 7.68 | L10: ="Companies visited: "&SUMPRODUCT((tblPlacements[Company]<>"")/COUNTIF(tblPlacements[Company],tblPlacements[Company]&""))&" (all years)" -> Companies visited: 26 (all years)
B42: ▲ TOP 10 PACKAGES | I42: ▼ LOWEST 10 PACKAGES (PLACED)
B43: # | C43: Student | D43: Branch | E43: Company | F43: LPA | G43: CGPA | I43: # | J43: Student | K43: Branch | L43: Company | M43: LPA | N43: CGPA
B44: 1 | C44: =IFERROR(INDEX(tblPlacements[Student Name],MATCH(LARGE(tblPlacements[Rank Key],$B44),tblPlacements[Rank Key],0)),"-") -> Nandini Rawat | D44: =IFERROR(INDEX(tblPlacements[Branch],MATCH(LARGE(tblPlacements[Rank Key],$B44),tblPlacements[Rank Key],0)),"-") -> IT | E44: =IFERROR(INDEX(tblPlacements[Company],MATCH(LARGE(tblPlacements[Rank Key],$B44),tblPlacements[Rank Key],0)),"-") -> Microsoft | F44: =IFERROR(INDEX(tblPlacements[Package LPA],MATCH(LARGE(tblPlacements[Rank Key],$B44),tblPlacements[Rank Key],0)),"-") -> 44.4 | G44: =IFERROR(INDEX(tblPlacements[CGPA],MATCH(LARGE(tblPlacements[Rank Key],$B44),tblPlacements[Rank Key],0)),"-") -> 8.6 | I44: 1 | J44: =IFERROR(INDEX(tblPlacements[Student Name],MATCH(SMALL(tblPlacements[Rank Key],$I44),tblPlacements[Rank Key],0)),"-") -> Rahul Singh | K44: =IFERROR(INDEX(tblPlacements[Branch],MATCH(SMALL(tblPlacements[Rank Key],$I44),tblPlacements[Rank Key],0)),"-") -> ECE | L44: =IFERROR(INDEX(tblPlacements[Company],MATCH(SMALL(tblPlacements[Rank Key],$I44),tblPlacements[Rank Key],0)),"-") -> Wipro | M44: =IFERROR(INDEX(tblPlacements[Package LPA],MATCH(SMALL(tblPlacements[Rank Key],$I44),tblPlacements[Rank Key],0)),"-") -> 3.5 | N44: =IFERROR(INDEX(tblPlacements[CGPA],MATCH(SMALL(tblPlacements[Rank Key],$I44),tblPlacements[Rank Key],0)),"-") -> 7.04
B45: 2 | C45: =IFERROR(INDEX(tblPlacements[Student Name],MATCH(LARGE(tblPlacements[Rank Key],$B45),tblPlacements[Rank Key],0)),"-") -> Kavya Kumar | D45: =IFERROR(INDEX(tblPlacements[Branch],MATCH(LARGE(tblPlacements[Rank Key],$B45),tblPlacements[Rank Key],0)),"-") -> CSE | E45: =IFERROR(INDEX(tblPlacements[Company],MATCH(LARGE(tblPlacements[Rank Key],$B45),tblPlacements[Rank Key],0)),"-") -> Microsoft | F45: =IFERROR(INDEX(tblPlacements[Package LPA],MATCH(LARGE(tblPlacements[Rank Key],$B45),tblPlacements[Rank Key],0)),"-") -> 42.2 | G45: =IFERROR(INDEX(tblPlacements[CGPA],MATCH(LARGE(tblPlacements[Rank Key],$B45),tblPlacements[Rank Key],0)),"-") -> 8.22 | I45: 2 | J45: =IFERROR(INDEX(tblPlacements[Student Name],MATCH(SMALL(tblPlacements[Rank Key],$I45),tblPlacements[Rank Key],0)),"-") -> Ananya Banerjee | K45: =IFERROR(INDEX(tblPlacements[Branch],MATCH(SMALL(tblPlacements[Rank Key],$I45),tblPlacements[Rank Key],0)),"-") -> CSE | L45: =IFERROR(INDEX(tblPlacements[Company],MATCH(SMALL(tblPlacements[Rank Key],$I45),tblPlacements[Rank Key],0)),"-") -> Infosys | M45: =IFERROR(INDEX(tblPlacements[Package LPA],MATCH(SMALL(tblPlacements[Rank Key],$I45),tblPlacements[Rank Key],0)),"-") -> 3.6 | N45: =IFERROR(INDEX(tblPlacements[CGPA],MATCH(SMALL(tblPlacements[Rank Key],$I45),tblPlacements[Rank Key],0)),"-") -> 5.95
B46: 3 | C46: =IFERROR(INDEX(tblPlacements[Student Name],MATCH(LARGE(tblPlacements[Rank Key],$B46),tblPlacements[Rank Key],0)),"-") -> Sakshi Verma | D46: =IFERROR(INDEX(tblPlacements[Branch],MATCH(LARGE(tblPlacements[Rank Key],$B46),tblPlacements[Rank Key],0)),"-") -> CSE | E46: =IFERROR(INDEX(tblPlacements[Company],MATCH(LARGE(tblPlacements[Rank Key],$B46),tblPlacements[Rank Key],0)),"-") -> Amazon | F46: =IFERROR(INDEX(tblPlacements[Package LPA],MATCH(LARGE(tblPlacements[Rank Key],$B46),tblPlacements[Rank Key],0)),"-") -> 37 | G46: =IFERROR(INDEX(tblPlacements[CGPA],MATCH(LARGE(tblPlacements[Rank Key],$B46),tblPlacements[Rank Key],0)),"-") -> 8.01 | I46: 3 | J46: =IFERROR(INDEX(tblPlacements[Student Name],MATCH(SMALL(tblPlacements[Rank Key],$I46),tblPlacements[Rank Key],0)),"-") -> Ananya Rawat | K46: =IFERROR(INDEX(tblPlacements[Branch],MATCH(SMALL(tblPlacements[Rank Key],$I46),tblPlacements[Rank Key],0)),"-") -> CSE | L46: =IFERROR(INDEX(tblPlacements[Company],MATCH(SMALL(tblPlacements[Rank Key],$I46),tblPlacements[Rank Key],0)),"-") -> Infosys | M46: =IFERROR(INDEX(tblPlacements[Package LPA],MATCH(SMALL(tblPlacements[Rank Key],$I46),tblPlacements[Rank Key],0)),"-") -> 3.6 | N46: =IFERROR(INDEX(tblPlacements[CGPA],MATCH(SMALL(tblPlacements[Rank Key],$I46),tblPlacements[Rank Key],0)),"-") -> 6.39
